Workbook
Name _xlcn.WorksheetConnection_BGMatl1: BGMatl[]
Name _xlcn.WorksheetConnection_Cells1: Cells[]
Name _xlcn.WorksheetConnection_Distributors1: Distributors[]
Name _xlcn.WorksheetConnection_EOL_Tbl1: EOL_Tbl[]
Name _xlcn.WorksheetConnection_Equip1: Equip[]
Name _xlcn.WorksheetConnection_Modeling1: Modeling[]
Name _xlcn.WorksheetConnection_Other1: Other[]
Name _xlcn.WorksheetConnection_PackMod1: PackMod[]
Name _xlcn.WorksheetConnection_RandD1: RandD[]
Name _xlcn.WorksheetConnection_RawMatl1: RawMatl[]
Name _xlcn.WorksheetConnection_Service1: Service[]
Name AEO: [2]Safety!$L$2
Name Co_2306: '[3]Co_CoSO4 forecast'!$V$182
Name Co_p25: '[3]Co_CoSO4 forecast'!$AA$25
Name Co_p50: '[3]Co_CoSO4 forecast'!$AA$24
Name Co_p75: '[3]Co_CoSO4 forecast'!$AA$23
Name compa: [4]PROVP!#REF!
Name Comparaison: [4]PROVP!$A:$A
Name cut_allowed_LT: [2]Safety!$L$6
Name cut_allowed_PC: [2]Safety!$L$5
Name cut_safety_LT: [2]Safety!$AK$8
Name cut_safety_PC: [2]Safety!$AK$7
Name ExternalData_1: Professional!#REF!
Name gC_kWh: [5]INPUTS!$B$32
Name gCO2_gC: [5]INPUTS!$B$34
Name Impres_titres_MI: [4]PROVP!$A:$A
Name Li_2306: [3]LCE!$V$170
Name Li_histprice: [3]LCE!$V$97:$V$170
Name Li_p25: [3]LCE!$AA$13
Name Li_p50: [3]LCE!$AA$12
Name Li_p75: [3]LCE!$AA$11
Name mode: [6]Config!$AD$7:$AD$19
Name Ni_2306: '[3]Ni_NiSO4 forecast'!$V$188
Name Ni_p25: '[3]Ni_NiSO4 forecast'!$AA$31
Name Ni_p50: '[3]Ni_NiSO4 forecast'!$AA$30
Name Ni_p75: '[3]Ni_NiSO4 forecast'!$AA$29
Name P91_: [4]PROVP!#REF!
Name P92_: [4]PROVP!#REF!
Name Renewable_and_Non_Renewable_Generation: [7]Contents!#REF!
Name Scenario: [8]Targets_byFleet!$A$1
Name T2MT: [9]Fuel_Specs!$F$135
Name TableName: "Dummy"
Name Transmission_loss: [5]kWhpMi!$G$1
Name UF_REEV20: [5]kWhpMi!$M$5
Name UF_REEV40: [5]kWhpMi!$M$4
Name WRcap_2021: [2]Safety!$L$3
Name WRcap_2025: [2]Safety!$L$4
Name Zone_impres_MI: [4]PROVP!$B$5:$B$90
Name _2014_eGRID_Subregion_File: #REF!
Name tblVspecsData: #REF!
Name tblVspecsHeader: #REF!
Name SearchType: 'Search List'!$A$2:$A$4
Name EOLSearch: 'Search List'!$C$2:$C$4
Name SearchType: #REF!
Name ExternalData_3: Append2!$A$1:$AN$1188
Name cost11: #REF!

Sheet literature review
C2: Yu et al., 2024 https://www.sciencedirect.com/science/article/abs/pii/S0378775323013319#:~:text=Manufacturing%20scraps%20refer%20to%20the,manufacturing%20scraps%20and%20spent%20batteries.&text=Not%20yet%20undergone%20cycling%20and,end%20of%20its%20operational%20lifespan.&text=Primarily%20from%20the%20used%20EVs%2C%20electronic%20devices%2C%20etc.
C4: "It’s reported that the scrap rate should be maintained below 10% to ensure profitability in battery manufacturing plants"
C6: "Circular Energy Storage (CES) estimates a global average scrap rate of 7.67% for 2023 and anticipates a decline to 4.34% by 2030 due to continuous improvements in the production process. However, at the current stage, given that many gigafactories are still taking steps to build plants and improve the manufacturing process, the rapid growth of the new production line results in high initial scrap rates."
C12: The ICCT data includes IRA-funded projecgts that are mostly planned facilities
C13: The NAATBatt data includes mostly those that are already commercial
C16: Operating capacity: https://www.broadn.io/blogs/on-us-manufacturing-capacity-utilization

Sheet Narrowed Manu facilities
A1: Source | B1: Status | C1: Supply Chain Segment | D1: Company | E1: Product/Facility Type | F1: Product | G1: Chemistry | H1: Facility State or Province | I1: Production Capacity | J1: Production Units | K1: Year online | L1: Notes on production capacity
A2: NaatBatt 2025 | C2: Midstream | D2: Blue Solutions Canada Inc. | G2: - | H2: QC | I2: 0.2 | J2: GWh/yr | K2: 2025 | L2: Solid state
A3: NaatBatt 2025 | C3: Midstream | D3: LI-CAP Technologies | G3: - | H3: CA | I3: 0.3 | J3: GWh/yr | K3: 2025 | L3: Cathode component https://www.nacleanenergy.com/energy-storage/licap-technologies-and-california-energy-commission-celebrate-major-milestone-in-u-s-battery-manufacturing-with-launch-of-300-mwh-dry-electrode-production-line?utm_source=chatgpt.com
A4: NaatBatt 2025 | C4: Midstream | D4: Enovix | G4: LCO | H4: CA | I4: 0.2 | J4: GWh/yr | K4: 2025
A5: NaatBatt 2025 | C5: Midstream | D5: Xerion Advanced Battery Corp | G5: LCO | H5: OH | I5: 1 | J5: GWh/yr | K5: 2025 | L5: https://www.iarpa.gov/images/PropsersDayPDFs/RESILIENCE/Xerion_Capabilities_Statement.pdf?utm_source=chatgpt.com
A6: NaatBatt 2025 | C6: Midstream | D6: Xerion Advanced Battery Corp | G6: LCO | H6: OH | K6: 2029 | L6: Refining
A7: NaatBatt 2025 | C7: Midstream | D7: Xerion Advanced Battery Corp | G7: LCO | H7: OH | K7: 2029 | L7: Refining
A8: NaatBatt 2025 | B8: Commercial | C8: Downstream | D8: Ford Motor Company | E8: Cell Assemblies/ Groupings | F8: Packs | G8: LFP | H8: MI | I8: 2 | J8: GWh/Yr | K8: 2025
A9: NaatBatt 2025 | B9: Commercial | C9: Downstream | D9: HiTHIUM Energy Storage Technology USA Inc. | E9: Assembly and Integration | F9: Battery Energy Storage | G9: LFP | H9: CA | I9: 10 | J9: GWh/yr | K9: 2025
A10: NaatBatt 2025 | B10: Commercial | C10: Downstream | D10: Lithion Battery | E10: Cell Assemblies/ Groupings | F10: Modules/ Arrays | G10: LFP | H10: NV | I10: 5 | J10: GWh/Yr | K10: 2025
A11: NaatBatt 2025 | B11: Commercial | C11: Downstream | D11: NP Power | E11: Manufacturing | F11: Cells and Cell Assemblies LPF and other chemistries | G11: LFP | H11: CA | I11: 2 | J11: GWh/yr | K11: 2025
A12: NaatBatt 2025 | B12: Commercial | C12: Downstream | D12: Sparkz Inc. | E12: Cell Assemblies/ Groupings | F12: Packs | G12: LFP | H12: CA | I12: 1 | J12: GWh/Yr | K12: 2025
A13: EDF | B13: Under construction | C13: Downstream | D13: Our Next Energy, Inc. | E13: Cell Assemblies/ Groupings | F13: Packs | G13: LFP | H13: MI | I13: 20 | J13: GWh/yr | K13: 2027 | L13: https://insideevs.com/news/615476/one-20gwh-battery-lfp-gigafactory-michigan/1000/
A14: EDF | C14: Downstream | D14: Canadian Solar | F14: Battery | G14: LFP | H14: TN | I14: 6 | J14: GWh/yr | K14: 2026 | L14: the note here makes it seem promising but there were a lot of large numbers online
A15: ICCT | C15: Downstream | D15: General Motors & Samsung SDI | F15: Battery | G15: LFP | H15: IN | I15: =36-27 -> 9 | J15: GWh/yr | K15: 2027 | L15: https://techcrunch.com/2023/06/13/gm-and-partner-samsung-sdi-pick-indiana-for-3b-battery-factory/#:~:text=Indiana%20Gov.,for%20most%20of%20its%20vehicles.
A16: NaatBatt 2025 | C16: Downstream | D16: Xos Trucks | F16: Packs | G16: LFP | H16: TN | I16: =2000*100/1000000 -> 0.2 | J16: GWh/yr | K16: 2025 | L16: https://www.aviseanalytics.com/xos-driving-a-path-to-profitability-in-the-ev-industry/#:~:text=for%20Xos%20products.-,Image%20Source:%20Company,changes%20and%20a%20second%20shift.
A17: NaatBatt 2025 | C17: Midstream | D17: A123 Systems | G17: LFP | H17: MI | I17: 0.969 | J17: GWh/yr | K17: 2025
A18: NaatBatt 2025 | C18: Midstream | D18: American Battery Factory | G18: LFP | H18: AZ | I18: 4 | J18: GWh/yr | K18: 2027
A19: NaatBatt 2025 | C19: Midstream | D19: Amplify Cell Technologies | G19: LFP | H19: MS | I19: 21 | J19: GWh/yr | K19: 2027 | L19: duplicate— https://www.businesswire.com/news/home/20240701093920/en/Amplify-Cell-Technologies-Begins-Construction-of-Mississippi-Battery-Cell-Factory?utm_source=chatgpt.com
A20: NaatBatt 2025 | C20: Midstream | D20: Dragonfly Energy Holdings Corp | G20: LFP | H20: NV | I20: 0.15 | J20: GWh/yr | K20: 2025
A21: NaatBatt 2025 | C21: Midstream | D21: Enpower Greentech | G21: LFP | H21: MI | I21: 0.2 | J21: GWh/yr | K21: 2025 | L21: https://www.enpower-energy.com/en/news/usa-battery-development-manufacturing-updates?utm_source=chatgpt.com
A22: NaatBatt 2025 | C22: Midstream | D22: e-Storage | G22: LFP | H22: KY | I22: 6 | J22: GWh/yr | K22: 2029
A23: NaatBatt 2025 | C23: Midstream | D23: Five Stone Energy | G23: LFP | H23: VA | K23: 2029 | L23: Not cell manufacturing
A24: NaatBatt 2025 | C24: Midstream | D24: Ford Motor Company | G24: LFP | H24: MI | I24: 20 | J24: GWh/yr | K24: 2029
A25: NaatBatt 2025 | C25: Midstream | D25: Gotion | G25: LFP | H25: MI | I25: 68 | J25: GWh/yr | K25: 2029 | L25: https://publications.anl.gov/anlpubs/2024/03/187735.pdf?utm_source=chatgpt.com
A26: EDF | C26: Midstream | D26: Guoxuan High Tech Co. | E26: LFP | F26: Cells | G26: LFP | H26: IL | I26: 50 | J26: GWh/yr | K26: 2024 | L26: https://www.evlithium.com/Blog/gotion-lifepo4-battery.html#:~:text=The%20factory%2C%20with%20a%20planned%20investment%20of,expected%20to%20go%20into%20production%20next%20year. https://www.batterytechonline.com/battery-manufacturing/gotion-in-motion-guoxuan-high-tech-keeps-going-growing
A27: NaatBatt 2025 | C27: Midstream | D27: LG Energy Solution Ltd | G27: LFP | H27: AZ | I27: 17 | J27: GWh/yr | K27: 2029
A28: NaatBatt 2025 | C28: Midstream | D28: Lithion Battery, Inc. | G28: LFP | H28: NV | I28: 0.2 | J28: GWh/yr | K28: 2025
A29: NaatBatt 2025 | C29: Midstream | D29: Lithion Battery, Inc. | G29: LFP | H29: AB | K29: 2025 | L29: Small facility
A30: NaatBatt 2025 | C30: Midstream | D30: Our Next Energy, Inc. | G30: LFP | H30: MI | I30: 0.01 | J30: GWh/yr | K30: 2025
A31: NaatBatt 2025 | C31: Midstream | D31: Pomega Energy Storage Technologies | G31: LFP | H31: SC | I31: 3 | J31: GWh/yr | K31: 2027
A32: NaatBatt 2025 | C32: Midstream | D32: Rolled-Ribbon Battery Company | G32: LFP | H32: TX | K32: 2025 | L32: Small facility https://www.crunchbase.com/organization/rolled-ribbon-battery-company?utm_source=chatgpt.com
A33: ICCT | C33: Midstream | D33: Sparkz | E33: LFP | F33: Cells | G33: LFP | H33: WV | I33: 15 | J33: GWh/yr | K33: 2028 | L33: https://autotechinsight.spglobal.com/feed?fs_site_area[0]=news&fs_tags[8][0]=41199
A34: NaatBatt 2025 | C34: Midstream | D34: Stryten Energy | G34: LFP | H34: KS | K34: 2025 | L34: Seem to focus on military
A35: NaatBatt 2025 | C35: Midstream | D35: Stryten Energy | G35: LFP | H35: ON | K35: 2025 | L35: Military
A36: NaatBatt 2025 | C36: Midstream | D36: Ultralife Corp | G36: LFP | H36: NY | I36: 0.05 | J36: GWh/yr | K36: 2025 | L36: https://www.ultralifecorp.com/ECommerce/product/ubi-2590/bb-2590-rechargeable-batteries/ubbl02-01-cb/ubi-2590-li-ion-cb
A37: NaatBatt 2025 | B37: Commercial | C37: Downstream | D37: Altairnano | E37: Cell Assemblies/ Groupings | F37: Modules/ Arrays | G37: LTO | H37: IN | I37: 0.26 | J37: GWh/yr | K37: 2025
A38: NaatBatt 2025 | C38: Midstream | D38: Altairnano | G38: LTO | H38: IN | I38: 0.26 | J38: GWh/yr | K38: 2025 | L38: https://pdf.secdatabase.com/219/0001437749-17-009565.pdf?utm_source=chatgpt.com
A39: NaatBatt 2025 | C39: Midstream | D39: ABSL Power Solutions, Inc. | G39: NA | H39: CO | K39: 2025 | L39: Military
A40: NaatBatt 2025 | B40: Commercial | C40: Downstream | D40: Clarios | E40: Cell Assemblies/ Groupings | F40: Packs | G40: NCA | H40: MI | I40: 2 | J40: GWh/yr | K40: 2025
...

Sheet Manu facilities incl removed
A1: Source | B1: Status | C1: Supply Chain Segment | D1: Included in old sheet? | E1: Company | F1: Facility Name | G1: Product/Facility Type | H1: Product | I1: Company Website | J1: Facility Address | K1: Facility City | L1: Facility State or Province | M1: Facility Country | N1: Facility Zip | O1: Facility Phone | P1: Latitude | Q1: Longitude | R1: Facility Workforce | S1: Production Capacity | T1: Production Units | U1: Year online | V1: Notes on production capacity | W1: HQ Company | X1: HQ Company Website | Y1: HQ City | Z1: HQ State or Province | AA1: HQ Country | AB1: QC | AC1: QC Date | AD1: Sources | AE1: Notes | AF1: Brief Company Profile | AG1: Sources2 | AH1: Summary Word Count | AI1: Contact | AJ1: Contact Email | AK1: Contact Phone | AL1: Column1
A2: NaatBatt 2025 | B2: Commercial | C2: Downstream | D2: N | E2: Altairnano | F2: Altairnano | G2: Cell Assemblies/ Groupings | H2: Modules/ Arrays | I2: https://altairnano.com/ | J2: 7307 Quality Circle | K2: Anderson | L2: IN | M2: US | N2: 46013 | O2: 317-333-7617 | P2: 40.040045 | Q2: -85.728025 | S2: 0.26 | T2: GWh/yr | U2: 2025 | W2: Altairnano | X2: https://altairnano.com/ | Y2: Reno | Z2: NV | AA2: US | AB2: EW MK | AC2: 8/9/2021 8/14/2025 | AD2: altairnano.com | AE2: LTO Battery Module; Closed its Reno manuf. Facility and moved it to China. Initial facility in Anderson is listed as permanently closed; BNEF does not list it; Unsure if it makes cells in US. Called and emailed | AF2: Altairnano leverages nanoscale technologies for powerful lithium titanate solutions. Its unique nano cells bring advantages to electric grid, transportation, and industrial applications. | AG2: https://altairnano.com/ | AH2: 22
A3: NaatBatt 2025 | E3: A123 Systems | L3: MI | S3: 0.969 | T3: GWh/yr | U3: 2025
A4: NaatBatt 2025 | B4: Commercial | C4: Downstream | D4: N | E4: AA Portable Power Corp. | F4: AA Portable Power Corp. | G4: Cell Assemblies/ Groupings | H4: Packs | I4: https://www.batteryspace.com/?gad=1&gclid=Cj0KCQjwk96lBhDHARIsAEKO4xY2o39jDdsYILun_GXH8PAloFNva54KUidx4aN6RDw6Uc46SGLc530aAjq2EALw_wcB | J4: 825 South 19th Street | K4: Richmond | L4: CA | M4: US | N4: 94804 | O4: 510-525-2328 | P4: 37.920848 | Q4: -122.35225 | R4: 30 | U4: 2025 | W4: AA Portable Power Corp. | X4: https://www.batteryspace.com/?gad=1&gclid=Cj0KCQjwk96lBhDHARIsAEKO4xY2o39jDdsYILun_GXH8PAloFNva54KUidx4aN6RDw6Uc46SGLc530aAjq2EALw_wcB | Y4: Richmond | Z4: CA | AA4: US | AB4: EW | AC4: 44417 | AD4: Thomasnet: Battery Packs / manufacturers; batteryspace.com | AE4: Mostly a battery distributor, but has production lines for custom order battery packs and battery testing. Workforce Range: 10-49 | AF4: AA Portable Power Corp. (dba: Batteryspace.com) was founded in 2000 and became a reputable battery manufacturer over the years. | AG4: https://www.batteryspace.com/?gad=1&gclid=Cj0KCQjwk96lBhDHARIsAEKO4xY2o39jDdsYILun_GXH8PAloFNva54KUidx4aN6RDw6Uc46SGLc530aAjq2EALw_wcB, https://www.batteryspace.com/contactus.aspx | AH4: 19
A5: NaatBatt 2025 | E5: ABSL Power Solutions, Inc. | L5: CO | S5: - | T5: GWh/yr | U5: 2025 | X5: Military
A6: NaatBatt 2025 | B6: Commercial | C6: Downstream | D6: y- updated capacity | E6: Accelera by Cummins | F6: Accelera | G6: Assembly and Integration | H6: Integrated Battery Packs for Trucks and Energy Storage | I6: https://www.accelerazero.com | J6: 500 Jackson St | K6: Columbus | L6: IN | M6: US | N6: 47201 | P6: 40.604878 | Q6: -85.858078 | S6: 2 | T6: GWh/yr | U6: 2025 | W6: Cummins | X6: https://www.cummins.com | Y6: Columbus | Z6: IN | AA6: US | AB6: AP | AC6: 45529 | AD6: https://www.cummins.com/news/releases/2023/03/08/cummins-launches-accelera-cummins-advance-transition-zero-emissions-future | AE6: CUMMINS LAUNCHES ACCELERA BY CUMMINS TO ADVANCE THE TRANSITION TO A ZERO-EMISSIONS FUTURE | AF6: Accelera by Cummins provides a diverse portfolio of zero-emission solutions including lithium batteries for the world’s most economically vital industries, empowering them to accelerate the transition to a sustainable future. | AH6: 30
A7: NaatBatt 2025 | B7: Pre-commercial/ startup | C7: Downstream | D7: N | E7: Acculon Energy | F7: Rev1 | G7: Cell Assemblies/ Groupings | H7: Packs | I7: https://acculonenergy.com/ | J7: 1305 Kinnear Rd | K7: Columbus | L7: OH | M7: US | N7: 43212 | O7: 614-259-7792 | P7: 39.997633 | Q7: -83.04217 | R7: 15 | S7: 2 | T7: GWh/yr | U7: 2025 | V7: https://acculonenergy.com/acculon-energy-announces-strategic-initiative-for-a-manufacturing-facility/ | W7: Acculon Energy | X7: https://acculonenergy.com/ | Y7: Columbus | Z7: OH | AA7: US | AB7: SD | AC7: 45432 | AD7: Questionnaire | AF7: Acculon Energy is a battery system developer and manufacturer. It provides an innovative end-to-end approach for accelerating market entry while minimizing risk during commercialization. | AG7: Questionnaire | AH7: 24 | AI7: Betsy Barry | AJ7: betsy.barry@acculonenergy.com | AK7: 706-206-7271
A8: NaatBatt 2025 | B8: Planned | C8: Downstream | D8: N | E8: AESC | F8: Bowling Green Plant | G8: Cell Assemblies/ Groupings | H8: Packs | I8: https://www.aesc-group.com/en/ | J8: Kentucky Transpark | K8: Bowling Green | L8: KY | M8: US | N8: 42101 | O8: 502-377-5675 | P8: 37.04 | Q8: -86.32 | R8: 2000 (Planned) | S8: 30 | T8: GWh/Yr | U8: 2026 | V8: Reports state 2025- but yet to be open https://us.aesc-group.com/aesc-celebrates-structural-completion-milestone-at-state-of-the-art-gigafactory-in-bowling-green/ | W8: AESC | X8: https://www.aesc-group.com/en/ | Y8: Zama | Z8: Kanagawa | AA8: Japan | AB8: KK MK | AC8: 8/4/2022 9/18/2025 | AD8: https://spectrumnews1.com/ky/bowling-green/news/2022/04/26/envision-aesc-plans-to-establish--2-billion-gigafactory-in-kentucky | AE8: Construction halted; plans uncertain | AF8: AESC Group leads a revolution with artificial intelligence converging with the internet of things-driven battery solutions, globally pioneering high-performance EV and energy storage, accelerating the shift to an endurable future. | AH8: 30
A9: NaatBatt 2025 | B9: Commercial | C9: Downstream | D9: N | E9: AESC | F9: Smyrna Battery Plant | G9: Cell Assemblies/ Groupings | H9: Packs | I9: https://www.aesc-group.com/en/ | J9: 500 Battery Plant Rd | K9: Smyrna | L9: TN | M9: US | N9: 37167 | O9: 615-768-3505 | P9: 36.217687 | Q9: -86.46103 | R9: 400 | S9: 40 | T9: GWj/Yr | U9: 2025 | V9: https://aesc-group.com/news/aesc-and-bmw-group-announce-new-partnership-in-battery-cell-production-and-supply | W9: AESC | X9: https://www.aesc-group.com/en/ | Y9: Zama | Z9: Kanagawa | AA9: Japan | AB9: VP MK | AC9: 8/1/2022 9/18/2025 | AD9: https://www.commercialappeal.com/story/money/2018/08/03/nissan-envision-group-take-control-smyrna-battery-plant/897768002/; https://www.dnb.com/business-directory/company-profiles.envision_aesc_(us)_llc.8a4477d46136013057715865676bc4c9.html | AE9: 2022 - Assembles battery packs for the Nissan Leaf; 2025 - Retooled for Energy Storage Systems (ESS) rather than EV | AF9: AESC Group leads a revolution with artificial intelligence converging with the internet of things-driven battery solutions, globally pioneering high-performance EV and energy storage, accelerating the shift to an endurable future. | AH9: 30
A10: NaatBatt 2025 | B10: Under construction | C10: Downstream | D10: N | E10: Akku Energy Devices LLC | F10: Akku Energy Devices LLC | G10: Manufacturing | H10: Packs | I10: https://akkuenergydevices.com/ | J10: 2650 E. 40th Ave. | K10: Denver | L10: CO | M10: US | N10: 80205 | O10: 303-808-4551 | P10: 39.771966 | Q10: -104.95529 | W10: Akku Energy Devices LLC | X10: https://akkuenergydevices.com/ | Y10: Denver | Z10: CO | AA10: US | AB10: MK | AC10: 45671 | AD10: Questionnaire | AF10: Akku Energy Devices LLC is a battery module and pack manufacturer specializing in micro-mobility, last-mile delivery vehicles, transportable energy storage, and stationary storage systems. | AH10: 24 | AI10: Bo Lee | AJ10: BoLee@evtico.com | AK10: 303-808-4551
A11: EDF | E11: AllCell Technology | H11: Modules/ Arrays | K11: Midland | L11: MI | S11: 0.0005064763 | T11: GWh/yr | U11: 2025
A12: NaatBatt 2025 | B12: Commercial | C12: Downstream | D12: N | E12: Alpha Technologies | F12: Alpha Technologies | G12: Cell Assemblies/ Groupings | H12: Modules/ Arrays | I12: https://www.alpha.com/ | J12: 1075 Satellite Blvd NW #100 | K12: Suwanee | L12: GA | M12: US | N12: 30024 | O12: 800-322-5742 | P12: 34.019067 | Q12: -84.069399 | U12: 2025 | W12: EnerSys | X12: https://www.enersys.com/en/ | Y12: Reading | Z12: PA | AA12: US | AB12: VP | AC12: 44429 | AD12: Questionnaire; enersys.com; alpha.com | AF12: Alpha Technologies, and EnerSys company, delivers integrated energy storage systems designed to meet the demands of a fast-evolving energy future, particularly in broadband and renewable energy applications. | AG12: https://www.alpha.com/, https://www.alpha.com/company/overview/about-alpha-technologies | AH12: 27
A13: NaatBatt 2025 | E13: Altairnano | L13: IN | S13: 0.26 | T13: GWh/yr | U13: 2025 | X13: https://pdf.secdatabase.com/219/0001437749-17-009565.pdf?utm_source=chatgpt.com
A14: NaatBatt 2025 | B14: Commercial | C14: Downstream | D14: N | E14: Ameresco | F14: Ameresco | G14: Assembly and Integration | H14: Battery Energy Storage | I14: https://www.ameresco.com/ | J14: 12211 W Alameda Pkwy, Suite 205 | K14: Lakewood | L14: CO | M14: US | N14: 80228 | O14: 720-627-8772 | P14: 39.705527 | Q14: -105.13842 | U14: 2025 | W14: Ameresco | X14: https://www.ameresco.com/ | Y14: Farmington | Z14: MA | AA14: US | AB14: AP | AC14: 45527 | AF14: Ameresco – an independent provider of innovative energy efficiency renewable energy solutions throughout North America - offers unique expertise across an array of green energy services including battery energy storage. | AH14: 30
A15: EDF | E15: American Autoparts, Inc (Mobis North America, LLC) | H15: Battery | K15: Midland | L15: MI | S15: 0.3311 | T15: GWh/yr | U15: 2027
A16: NaatBatt 2025 | E16: American Battery Factory | L16: AZ | S16: 4 | T16: GWh/yr | U16: 2027
A17: ICCT | E17: American Battery Factory | H17: Battery | K17: Coweta County | L17: Georgia | S17: 15 | T17: GWh/yr | U17: 2025 | V17: https://americanbatteryfactory.com/production
A18: NaatBatt 2025 | B18: Commercial | C18: Downstream | D18: Y | E18: American Battery Solutions | F18: Headquarters & Innovation Center | G18: Battery Development | H18: Packs Modules | I18: https://www.americanbatterysolutions.com/ | J18: 3768 S. Lapeer Road | K18: Lake Orion | L18: MI | M18: US | N18: 48539 | O18: 248-462-6364 | P18: 42.727073 | Q18: -83.243593 | R18: 156 | S18: =2/1000 -> 0.002 | T18: GWh/Yr | U18: 2025 | W18: Komatsu America | X18: https://www.americanbatterysolutions.com/ | Y18: Lake Orion | Z18: MI | AA18: US | AB18: VP AP | AC18: 8/6/2022 9/13/2024 | AD18: americanbatterysolutions.com/high-voltage; dnb.com/business-directory/company-profiles.american_battery_solutions_inc; Questionnaire; https://www.americanbatterysolutions.com/news-articles/american-battery-solutions-announces-re-launch-of-springboro-ohio-manufacturing-facility-with-added-capacity-to-meet-growing-lithium-ion-battery-demand; https://www.oemoffhighway.com/electronics/power-systems/batteries-capacitors/company/22005710/american-battery-solutions#:~:text=Our%20manufacturing%20team%20has%20produced,motive%20industrial%2C%20and%20commercial%20sectors. | AE18: Assembles battery packs for Fiat; 8 MWh/y expected production 2025 for 150,000 vehicles; Production capacity was estimated from current production of 60k packs to 150k packs corresponding to 8 MWh | AF18: American Battery Solutions delivered high-quality lithium-ion integrated battery solutions to meet energy needs | AG18: https://www.americanbatterysolutions.com/ | AH18: 13 | AI18: John Warner | AJ18: jwarner@americanbatterysolutions.com | AK18: 8109194751
A19: NaatBatt 2025 | B19: Commercial | C19: Downstream | D19: N | E19: American Battery Solutions | F19: ABS Innovation Center | G19: Battery Development | H19: Packs | I19: https://www.americanbatterysolutions.com/ | J19: 8110 Drouet Dr | K19: Springboro | L19: OH | M19: US | N19: 45066 | O19: 937-743-5296 | P19: 39.5532 | Q19: 84.2625 | S19: 2 | T19: GWh/Yr | U19: 2025 | W19: Komatsu America | X19: https://www.americanbatterysolutions.com/ | Y19: Lake Orion | Z19: MI | AA19: US | AB19: MK | AC19: 45918 | AD19: https://www.americanbatterysolutions.com/facilities; https://www.prnewswire.com/news-releases/american-battery-solutions-announces-re-launch-of-springboro-ohio-manufacturing-facility-with-added-capacity-to-meet-growing-lithium-ion-battery-demand-301516527.html | AF19: American Battery Solutions delivers high-quality lithium-ion integrated battery solutions to meet energy needs | AH19: 13 | AI19: John Warner | AJ19: jwarner@americanbatterysolutions.com | AK19: 8109194751
A20: NaatBatt 2025 | B20: Pre-commercial/ startup | C20: Downstream | D20: Y | E20: American Lithium Energy | F20: American Lithium Energy | G20: Cell Assemblies/ Groupings | H20: Packs | I20: https://www.americanlithiumenergy.com/ | J20: 2261 Rutherford Rd | K20: Carlsbad | L20: CA | M20: US | N20: 92008 | O20: 760-444-5244 | P20: 33.131818 | Q20: -117.27596 | R20: 13 | S20: 0.2 | T20: GWh/Yr | U20: 2025 | W20: American Lithium Energy | X20: https://www.americanlithiumenergy.com/ | Y20: Carlsbad | Z20: CA | AA20: US | AB20: VP MK | AC20: 8/1/2022 9/18/2025 | AD20: americanlithiumenergy.com; https://www.datanyze.com/companies/american-lithium-energy/347887839 | AE20: Focuses on batteries and packs for military applications | AF20: American Lithium Energy ships the world's highest energy density silicon anode lithium-ion batteries. | AG20: https://www.americanlithiumenergy.com/, https://www.americanlithiumenergy.com/about | AH20: 13
A21: NaatBatt 2025 | E21: Amplify Cell Technologies | L21: MS | S21: 21 | T21: GWh/yr | U21: 2027 | X21: duplicateâ€” https://www.businesswire.com/news/home/20240701093920/en/Amplify-Cell-Technologies-Begins-Construction-of-Mississippi-Battery-Cell-Factory?utm_source=chatgpt.com
A22: EDF | E22: Amplify Cell Technologies (Accelera, EVE and PACCAR and Daimler) | H22: Battery Component | K22: Liberty | L22: North Carolina | S22: 21 | T22: GWh/yr | U22: 2027 | V22: Amplify Cell Technologies (Accelera, EVE and PACCAR and Daimler)
A23: NaatBatt 2025 | B23: Under construction | C23: Downstream | D23: N | E23: Archer Aviation Inc | F23: Archer Aviation | G23: Assembly and Integration | H23: Packs | I23: https://archer.com/ | J23: 12000 GA-142 | K23: Covington | L23: GA | M23: US | N23: 30014 | P23: 33.6335 | Q23: -83.8475 | R23: 1000 | S23: 5.538 | T23: GWh/Yr | U23: 2027 | V23: Estimating a year after their UAE launch: https://finance.yahoo.com/news/where-archer-aviation-3-years-102300455.html 142 kwh * 6 = 852 kwh per aircraft * 650 aircraft = | W23: Archer Aviation Inc | X23: https://archer.com/ | Y23: San Jose | Z23: CA | AA23: US | AB23: MK | AC23: 45876 | AD23: https://www.airport-technology.com/news/archer-aircraft-facility-georgia/#:~:text=Archer%20Aviation%20has%20completed%20the%20construction%20of%20its,the%20facility%20covers%20an%20area%20of%20about%20400%2C000ft%C2%B2 | AE23: Construction on Phase 1 of this 350,000 sq ft high-volume manufacturing plant began in 2023. It will produce Archer's proprietary battery packs and assemble the "Midnight" aircraft | AF23: Archer is a leader in the electric, vertical take-off and landing space, developing electric air taxis to revolutionize urban transportation with safe and low-noise aircraft. | AH23: 25
A24: NaatBatt 2025 | B24: Pre-commercial/ startup | C24: Downstream | D24: N | E24: Archer Aviation Inc | F24: Archer Aviation | G24: Assembly and Integration | H24: Packs | I24: https://archer.com/ | J24: 190 W Tasman Dr | K24: San Jose | L24: CA | M24: US | N24: 95134 | P24: 37.4102 | Q24: -121.9456 | W24: Archer Aviation Inc | X24: https://archer.com/ | Y24: San Jose | Z24: CA | AA24: US | AB24: MK | AC24: 45876 | AD24: https://www.molicel.com/newsroom/archer-selects-molicel-to-supply-battery-cells-for-midnighttm/ | AE24: They have a strategic partnership with Molicel for the supply of high-performance lithium-ion cells for their "Midnight" aircraft | AF24: Archer is a leader in the electric, vertical take-off and landing space, developing electric air taxis to revolutionize urban transportation with safe and low-noise aircraft. | AH24: 25
A25: NaatBatt 2025 | B25: Commercial | C25: Downstream | D25: N | E25: Arkema | F25: Arkema - Bostik Adhesives | G25: Non-cell Components | H25: Other/ Unknown | I25: https://www.arkema.com/global/en/ | J25: 1301 N. 113th St | K25: Wauwatosa | L25: WI | M25: US | N25: 53226 | O25: 270-395-7121 | P25: 43.047414 | Q25: -88.053951 | U25: 2025 | W25: Arkema | X25: https://www.arkema.com/global/en/ | Y25: King of Prussia | Z25: PA | AA25: US | AB25: VP | AC25: 44421 | AD25: Questionnaire; Arkema.com | AE25: Adhesives | AF25: Arkema, a leader in specialty materials, leverages its expertise in materials science to create innovative, sustainable materials, and particularly providing necessary materials for lithium-ion cell manufacturing | AG25: https://www.arkema.com/global/en/, https://www.arkema.com/global/en/arkema-group/profile/ | AH25: 26
A26: ICCT | E26: BASF | H26: Cathode | K26: Lansing | L26: Michigan | S26: 1.6666667 | T26: GWh/yr | U26: 2024
A27: NaatBatt 2025 | B27: Commercial | C27: Downstream | D27: N | E27: Battery Specialties | F27: Battery Specialties | G27: Cell Assemblies/ Groupings | H27: Packs | I27: https://batteryspecialties.com/ | J27: 3530 Cadillac Ave. | K27: Costa Mesa | L27: CA | M27: US | N27: 92626 | O27: 800-854-5759 | P27: 33.697464 | Q27: -117.93002 | R27: 35 | U27: 2025 | W27: Battery Specialties | X27: https://batteryspecialties.com/ | Y27: Costa Mesa | Z27: CA | AA27: US | AB27: VP | AC27: 44774 | AD27: Thomasnet: Battery Packs / manufacturers; https://www.zoominfo.com/c/battery-specialties/8523659 | AE27: Custom battery packs, usually for military use; | AF27: Battery Specialties is involved in industrial and commercial battery distribution. | AG27: https://batteryspecialties.com/, https://batteryspecialties.com/about | AH27: 10
A28: NaatBatt 2025 | B28: Commercial | C28: Downstream | D28: N | E28: Beam | F28: Broadview | G28: Cell Assemblies/ Groupings | H28: Modules/ Arrays | I28: https://beamforall.com/ | J28: 2600 S 25th Ave, Suite Z | K28: Broadview | L28: IL | M28: US | N28: 60155 | O28: 872-281-7606 | P28: 41.854977 | Q28: -87.864275 | R28: 44 | U28: 2025 | W28: Beam Global | X28: https://beamforall.com/ | Y28: San Diego | Z28: CA | AA28: US | AB28: VP MK | AC28: 8/1/2022 9/18/2025 | AD28: allcelltech.com; Questionnaire; https://www.buzzfile.com/business/Allcell-Technologies-872-281-7606; https://beamforall.com/beam-global-announces-strategic-acquisition-of-allcell-technologies-a-leader-in-energy-storage-solutions/ | AE28: Battery packs using thermal interphase materials; All Cell tech was acquired by Beam | AF28: AllCell Technology produces safe lithium-ion batteries. | AG28: https://www.allcelltech.com/index.php/, https://www.allcelltech.com/index.php/about-us/allcell-overview/ | AH28: 6
A29: NaatBatt 2025 | B29: Commercial | C29: Downstream | D29: N | E29: BETA Technologies | F29: South Burlington Production Facility | G29: Assembly and Integration | H29: Packs | I29: https://beta.team/ | J29: 1550 Williston Rd | K29: South Burlington | L29: VT | M29: US | N29: 05403 | O29: 802-281-3623 | P29: 44.4682 | Q29: -73.1555 | U29: 2025 | W29: BETA Technologies | X29: https://beta.team/ | Y29: South Burlington | Z29: VT | AA29: US | AB29: MK | AC29: 45876 | AD29: https://beta.team/ | AE29: This is BETA's primary 188,000 sq ft manufacturing and assembly facility where they build their aircraft and assemble the battery packs. It is located at the Patrick Leahy Burlington International Airport | AF29: BETA Technologies is an aerospace company developing and manufacturing electric flight and charging systems for the logistics, medical, defense, and passenger sectors. | AH29: 22
A30: NaatBatt 2025 | B30: Commercial | C30: Downstream | D30: N | E30: Black Teal Energy | F30: Black Teal Energy | G30: Cell Assemblies/ Groupings | H30: Enclosures, aftermarket EV batteries, Energy Storage Systems | I30: https://www.blacktealenergy.com/ | J30: 3951 Research Drive, Suite D | K30: Sacramento | L30: CA | M30: US | N30: 95838 | O30: 310-525-5296 | P30: 38.639532 | Q30: -121.45952 | R30: 22 | U30: 2025 | W30: Black Teal Energy | X30: https://www.blacktealenergy.com/ | Y30: Sacramento | Z30: CA | AA30: US | AB30: AP | AC30: 45336 | AD30: https://www.blacktealenergy.com/ | AF30: Black Teal Energy focuses on sustainable energy solutions, offering aftermarket batteries for electric vehicles and energy storage systems, aiming for 100% recyclability and extending the lifespan of battery materials. | AH30: 29
A31: NaatBatt 2025 | B31: Commercial | C31: Downstream | D31: N | E31: Blue Line Battery, Inc. | F31: Blue Line Battery, Inc. | G31: Cell Assemblies/ Groupings | H31: Packs | I31: https://bluelinebattery.com/ | J31: 601 3rd St | K31: Beloit | L31: WI | M31: US | N31: 53511 | O31: 262-501-3376 | P31: 42.503144 | Q31: -89.03522 | R31: 12 | U31: 2025 | W31: Blue Line Battery, Inc. | X31: https://bluelinebattery.com/ | Y31: Whitewater | Z31: WI | AA31: US | AB31: KK | AC31: 44774 | AD31: https://bluelinebattery.com/products/ | AE31: Manufacturer of lithium-ion batteries designed for multiple and varied industrial applications. The company develops water and impact-resistant batteries for applications such as electric bikes, power storage, remote controls, and industrial purposes, enabling companies across various industries to meet and fulfill motive power and stationary energy storage needs. | AF31: Blue Line Battery focuses on the next stage in lithium-ion technology. | AG31: https://bluelinebattery.com/, https://bluelinebattery.com/about/ | AH31: 11
A32: NaatBatt 2025 | B32: Commercial | C32: Downstream | D32: N | E32: Blue Solutions Canada Inc. | F32: Blue Solutions Canada Inc. | G32: Cell Assemblies/ Groupings | H32: Packs | I32: https://www.blue-solutions.ca/ | J32: 1601 Rue de Coulomb | K32: Boucherville | L32: QC | M32: Canada | N32: J4B 8J7 | O32: 450-655-6622 | P32: 45.556091 | Q32: -73.425186 | R32: 228 | U32: 2025 | W32: Blue Solutions Canada Inc. | X32: https://www.blue-solutions.ca/ | Y32: Boucherville | Z32: QC | AA32: Canada | AB32: VP | AC32: 44414 | AD32: Questionnaire; https://www.zoominfo.com/pic/blue-solutions/372118582 | AF32: Blue Solutions Canada has the only solid-state 100% on the market. | AG32: https://www.blue-solutions.ca/ | AH32: 11
A33: NaatBatt 2025 | B33: Commercial | C33: Downstream | D33: N | E33: BlueOvalSK (JV - Ford and SK ON) | F33: 1 Blue Oval | G33: Cell Assemblies/ Groupings | H33: Packs | I33: https://blueovalsk.com/kentucky | J33: 1 BlueOval | K33: Glendale | L33: KY | M33: US | N33: 42740 | P33: 37.6 | Q33: -85.9 | R33: 5000 (Planned) | S33: 20 | T33: GWh/Yr | U33: 2025 | W33: S K Innovation | X33: https://blueovalsk.com/ | Y33: Jongno-gu | Z33: Seoul | AA33: S Korea | AB33: VP MK | AC33: 6/19/2023 9/18/2025 | AD33: https://www.kentucky.com/news/state/kentucky/article254556442.html; BNEF Interactive Dataset\Cell Manufacturing; https://blueovalsk.com/kentucky/; https://www.charged-the-book.com/na-ev-supply-chain-map; https://www.lanereport.com/183196/2025/08/multibillion-dollar-blueoval-sk-ev-battery-plants-launch-production/ | AF33: BlueOvalSK's mega campus is envisioned to be an endurable automotive manufacturing ecosystem. | AG33: https://blueovalsk.com/kentucky, https://www.blueovalsk.com/ | AH33: 12
A34: NaatBatt 2025 | B34: Planned | C34: Downstream | D34: N | E34: BlueOvalSK (JV - Ford and SK ON) | F34: Blue Oval City | G34: Cell Assemblies/ Groupings | H34: Packs | I34: https://blueovalsk.com/tennessee | J34: Blue Oval City | K34: Stanton | L34: TN | M34: US | N34: 38069 | P34: 35.402916 | Q34: -89.417312 | R34: 5800 (Planned) | S34: 43 | T34: GWh/Yr | U34: 2027 | V34: https://www.commercialappeal.com/story/money/business/2025/08/19/blueoval-sk-battery-production-delay-west-tennessee/85725474007/ | W34: S K Innovation | X34: https://blueovalsk.com/ | Y34: Jongno-gu | Z34: Seoul | AA34: S Korea | AB34: VP MK | AC34: 8/4/2022 9/18/2025 | AD34: https://www.kentucky.com/news/state/kentucky/article254556442.html; https://www.commercialappeal.com/story/money/business/2022/07/14/ford-sk-on-ev-battery-plant-west-tennessee-blue-oval-city/10038277002/; BNEF Interactive Dataset\Cell Manufacturing; https://www.lanereport.com/183196/2025/08/multibillion-dollar-blueoval-sk-ev-battery-plants-launch-production/ | AE34: Commissioning expected in by EOY 2027 | AF34: BlueOvalSK's mega campus is envisioned to be an endurable automotive manufacturing ecosystem. | AG34: https://blueovalsk.com/tennessee, https://www.blueovalsk.com/ | AH34: 12
A35: ICCT | E35: BMW AG | H35: Modules, Packs | K35: Warren | L35: Ohio | S35: 1.68 | T35: GWh/yr | U35: 2024
A36: NaatBatt 2025 | B36: Under construction | C36: Downstream | D36: N | E36: BMW Group Inc | F36: BMW San Luis Potosi Battery Manufacturing Plant | G36: Assembly and Integration | H36: Packs | I36: https://www.bmwgroup-werke.com/san-luis-potosi/es.html | J36: Boulevard BMW No. 655 Parque Industrial Desarrollo Logistik II | K36: San Luis Potosi | L36: San Luis Potosi | M36: Mexico | N36: 79526 | O36: 52-444-347-9137 | P36: 22.462813 | Q36: -100.8707 | R36: 500 (Planned) | S36: 8.75 | T36: GWh/yr | U36: 2026 | V36: https://www.bmwblog.com/2024/10/30/bmw-lithium-battery-production-mexico-san-luis-potosi/ | W36: BMW Group | X36: https://www.bmwgroup-werke.com | Y36: Munich | Z36: Bavaria | AA36: Germany | AB36: VP MK | AC36: 6/7/2023 8/14/2025 | AD36: https://www.bmwgroup-werke.com/san-luis-potosi/es/noticias/pressreleases/2023/neue-klasse.html#1022952825; BNEF Cell DB; https://mexico-now.com/bmw-group-to-produce-electric-vehicles-and-high-voltage-batteries-in-slp/ | AE36: 2027 SOP | AF36: BMW, a major car maker, develops and integrates advanced lithium-ion batteries for electric vehicles, focusing on enhancing energy density, efficiency, lifespan, and safety, while collaborating with technology partners for innovation. | AG36: https://www.bmwgroup-werke.com/san-luis-potosi/en.html, https://www.bmwgroup.com/en/investor-relations/company-reports.html | AH36: 30
A37: NaatBatt 2025 | B37: Commercial | C37: Under Construction | D37: N | E37: BMW Manufacturing | F37: Spartanburg Manufacturing Plant | G37: Cell Assemblies/ Groupings | H37: Packs | I37: https://www.bmwgroup-werke.com/en.html | K37: Woodruff | L37: SC | M37: US | N37: 29651 | O37: 864-802-6000 | P37: 34.894648 | Q37: -82.180366 | R37: 120 | S37: =22500*80/1000000 -> 1.8 | T37: GWh/yr | U37: 2025 | V37: 22500 units per year, assuming each unit is 80 kwh | W37: BMW Group | X37: https://www.bmwusa.com/ | Y37: Munich | Z37: Bavaria | AA37: Germany | AB37: EW MK | AC37: 8/9/2021 9/18/2025 | AD37: EV Battery Supply Chain Analysis https://www.automotivelogistics.media/battery-supply-chain/oem-and-lithium-ion-battery-cell-supplier-database/41933.article; bmwusa.com; https://www.bmwgroup-werke.com/spartanburg/en/our-plant/site-infos.html#ace-2129196916; https://www.bmwgroup.com/en/news/general/2024/batteryproduction.html | AE37: Assembles battery packs for BMW; 120 are employed in battery production; 11,000 are employed at the entire plant. Estimated prod. Based on 45,000 batteries in 4 years and doubling capacity in 2019- https://www.bmwgroup-werke.com/spartanburg/en/our-plant/site-infos.html#ace-2129196916 | AF37: BMW Manufacturing, a subsidiary of BMW Group, assembles several vehicle models and battery packs in this 8 million square-foot campus in Greer, South Carolina. | AG37: https://www.bmwgroup-werke.com/en.html | AH37: 24
A38: NaatBatt 2025 | B38: Commercial | C38: Downstream | D38: Y | E38: BMZ USA Inc. | F38: BMZ Virginia Beach Battery Manufacturing Plant | G38: Assembly and Integration | H38: Packs | I38: https://www.bmz-group.com/index.php/en/ | J38: 1429 Miller Store Rd. | K38: Virginia Beach | L38: VA | M38: US | N38: 23455 | O38: 757-821-8494 | P38: 36.895567 | Q38: -76.191425 | R38: 100 | S38: 2 | T38: GWh/yr | U38: 2025 | W38: BMZ Co GmBH | X38: bmz-group.com | Y38: Karlstein am Main | Z38: Bavaria | AA38: Germany | AB38: VP MK | AC38: 6/7/2023 8/14/2025 | AD38: bmz-group.com; BNEF Cell Database; https://www.bestmag.co.uk/bmz-selects-new-us-headquarters-virginia-beach/ | AF38: BMZ innovates high-tech batteries for global brands, integrating cutting-edge tech. Its one-stop-shop ensures excellence across the value chain, from production to after-sales. | AG38: https://www.bmz-group.com/index.php/en/ | AH38: 22
A39: EDF | E39: BorgWarner | H39: Battery | K39: Spring Hill | L39: Tennessee | S39: 3 | T39: GWh/yr | U39: 2024 | V39: https://finance.yahoo.com/news/borgwarner-bwa-makes-62m-electrification-113411082.html
A40: NaatBatt 2025 | B40: Commercial | C40: Downstream | D40: N | E40: Braille Battery, Inc | F40: Braille Battery, Inc | G40: Cell Assemblies/ Groupings | H40: Packs | I40: https://braillebattery.com/ | J40: 6935 15th St E | K40: Sarasota | L40: FL | M40: US | N40: 34243 | O40: 941-312-5047 | P40: 27.417407 | Q40: -82.545679 | R40: 15 | U40: 2025 | W40: Braille Battery Inc. | X40: https://braillebattery.com/ | Y40: Sarasota | Z40: FL | AA40: US | AB40: VP | AC40: 44781 | AD40: braillebattery.com; https://www.zoominfo.com/c/braille-battery-inc/353980518; https://www.linkedin.com/company/braille-battery | AE40: Manufacture specialty Li-ion batteries for racing cars and other high performance applications; Workforce < 25 or 11-50; Estimated 15 | AF40: Braille Battery is a world leader in light-weight AGM batteries. | AG40: https://braillebattery.com/, https://braillebattery.com/our-story/ | AH40: 10
...

Sheet production capacity sum
A3: Sum of Production Capacity | B3: Midstream
A4: 2025 | B4: Downstream | C4: Midstream | D4: Grand Total
B5: 0 | D5: 0
A6: 2023 | B6: 90 | D6: 90
A7: 2024 | B7: 23 | C7: 50 | D7: 73
A8: 2025 | B8: 504.72304 | C8: 173.865 | D8: 678.58804
A9: 2026 | B9: 312.96603 | C9: 33 | D9: 345.96603
A10: 2027 | B10: 256.768 | C10: 379.7 | D10: 636.468
A11: 2028 | B11: 130 | C11: 15 | D11: 145
A12: 2029 | C12: 411 | D12: 411
A13: 2030 | B13: 32 | D13: 32
B14: 0 | D14: 0
A15: Grand Total | B15: 1349.4571 | C15: 1062.565 | D15: 2412.0221
B17: yearly
B18: Downstream | C18: Midstream | D18: Total
A19: 2023 | B19: 90 | D19: 90
A20: 2024 | B20: 23 | C20: 50 | D20: 73
A21: 2025 | B21: 504.72304 | C21: 174.065 | D21: 678.78804
A22: 2026 | B22: 312.96603 | C22: 33 | D22: 345.96603
A23: 2027 | B23: 256.768 | C23: 379.7 | D23: 636.468
A24: 2028 | B24: 130 | C24: 15 | D24: 145
A25: 2029 | C25: 411 | D25: 411
A26: 2030 | B26: 32 | D26: 32
B29: total
B30: Downstream | C30: Midstream | D30: Total | E30: % loss | F30: Midstream loss | G30: Downstream loss | H30: GWh midstream manufacturing loss | I30: GWh downstream manufacturing loss
A31: 2023 | B31: =B19*F42 -> 69.3 | C31: =C19 | D31: =SUM(B31:C31) -> 69.3 | E31: 0.0767 | F31: =E31*$F$40 -> 0.05 | G31: =E31-F31 -> 0.0267 | H31: =F31*C31 -> 0 | I31: =B31*G31 -> 1.85031
A32: 2024 | B32: =(B20*$F$42)+B31 -> 87.01 | C32: =(C20*$F$42)+C31 -> 38.5 | D32: =SUM(B32:C32) -> 125.51 | E32: =E31-((E$31-E$38)/7) -> 0.071942857 | F32: =E32*$F$40 -> 0.046898864 | G32: =E32-F32 -> 0.025043993 | H32: =F32*C32 -> 1.8056063 | I32: =B32*G32 -> 2.1790779
A33: 2025 | B33: =(B21*$F$42)+B32 -> 475.64674 | C33: =(C21*$F$42)+C32 -> 172.53005 | D33: =SUM(B33:C33) -> 648.17679 | E33: =E32-((E$31-E$38)/7) -> 0.067185714 | F33: =E33*$F$40 -> 0.043797728 | G33: =E33-F33 -> 0.023387987 | H33: =F33*C33 -> 7.5564241 | I33: =B33*G33 -> 11.12442
A34: 2026 | B34: =(B22*$F$42)+B33 -> 716.63058 | C34: =(C22*$F$42)+C33 -> 197.94005 | D34: =SUM(B34:C34) -> 914.57063 | E34: =E33-((E$31-E$38)/7) -> 0.062428571 | F34: =E34*$F$40 -> 0.040696592 | G34: =E34-F34 -> 0.02173198 | H34: =F34*C34 -> 8.0554854 | I34: =B34*G34 -> 15.573801
A35: 2027 | B35: =(B23*$F$42)+B34 -> 914.34194 | C35: =(C23*$F$42)+C34 -> 490.30905 | D35: =SUM(B35:C35) -> 1404.651 | E35: =E34-((E$31-E$38)/7) -> 0.057671429 | F35: =E35*$F$40 -> 0.037595455 | G35: =E35-F35 -> 0.020075973 | H35: =F35*C35 -> 18.433392 | I35: =B35*G35 -> 18.356304
A36: 2028 | B36: =(B24*$F$42)+B35 -> 1014.4419 | C36: =(C24*$F$42)+C35 -> 501.85905 | D36: =SUM(B36:C36) -> 1516.301 | E36: =E35-((E$31-E$38)/7) -> 0.052914286 | F36: =E36*$F$40 -> 0.034494319 | G36: =E36-F36 -> 0.018419966 | H36: =F36*C36 -> 17.311286 | I36: =B36*G36 -> 18.685987
A37: 2029 | B37: =(B25*$F$42)+B36 -> 1014.4419 | C37: =(C25*$F$42)+C36 -> 818.32905 | D37: =SUM(B37:C37) -> 1832.771 | E37: =E36-((E$31-E$38)/7) -> 0.048157143 | F37: =E37*$F$40 -> 0.031393183 | G37: =E37-F37 -> 0.01676396 | H37: =F37*C37 -> 25.689954 | I37: =B37*G37 -> 17.006064
A38: 2030 | B38: =(B26*$F$42)+B37 -> 1039.0819 | C38: =(C26*$F$42)+C37 -> 818.32905 | D38: =SUM(B38:C38) -> 1857.411 | E38: 0.0434 | F38: =E38*$F$40 -> 0.028292047 | G38: =E38-F38 -> 0.015107953 | H38: =F38*C38 -> 23.152204 | I38: =B38*G38 -> 15.698401
E40: cell loss as percent of total loss | F40: =0.05/E31 -> 0.65189048
E42: Operating capacity | F42: 0.77

Sheet Electrode & Cell Manufacturing
A1: ID | B1: Status | C1: Supply Chain Segment | D1: Company | E1: NAATBatt Member | F1: Facility Name | G1: Product/Facility Type | H1: Product | I1: Company Website | J1: Facility Address | K1: Facility City | L1: Facility State or Province | M1: Facility Country | N1: Facility Zip | O1: Facility Phone | P1: Latitude | Q1: Longitude | R1: Facility Workforce | S1: Production Capacity | T1: Production Units | U1: HQ Company | V1: HQ Company Website | W1: HQ City | X1: HQ State or Province | Y1: HQ Country | Z1: QC | AA1: QC Date | AB1: Sources | AC1: Notes | AD1: Brief Company Profile | AE1: Sources2 | AF1: Summary Word Count | AG1: Contact | AH1: Contact Email | AI1: Contact Phone | AJ1: Column1
A2: 4008 | B2: Commercial | C2: Midstream | D2: Altairnano | E2: No | F2: Altairnano | G2: Prismatic pouch cells | H2: Lithium titanium oxide | I2: https://altairnano.com/ | J2: 7311 Quality Circle | K2: Anderson | L2: IN | M2: US | N2: 46013 | O2: 317-333-7617 | P2: 40.040127 | Q2: -85.728122 | R2: 106 | U2: Altairnano | V2: https://altairnano.com/ | W2: Reno | X2: NV | Y2: US | Z2: VP | AA2: 8/4/2022 8/14/2025 | AB2: altairnano.com;https://www.sec.gov/Archives/edgar/data/1016546/000143774916042208/alti20160922_10k.htm;https://en.wikipedia.org/wiki/Altairnano | AC2: Closed its Reno manuf. Facility and moved it to China. Initial facility in Anderson is listed as permanently closed; BNEF does not list it; Unsure if it makes cells in US. Called and emailed. Used to be called Altair Nanotechnologies | AD2: Altairnano leverages nanoscale technologies for powerful lithium titanate solutions. Its unique nano cells bring advantages to electric grid, transportation, and industrial applications. | AE2: https://altairnano.com/ | AF2: =IF(LEN(TRIM(AD2))=0,0,LEN(TRIM(AD2))-LEN(SUBSTITUTE(AD2," ",""))+1) -> 22
A3: 4001 | B3: Commercial | C3: Midstream | D3: A123 Systems | E3: No | F3: A123 Advanced Engineering Center | G3: Other/ Unknown cells | H3: Lithium iron phosphate | I3: http://www.a123systems.com/ | J3: 27101 Cabaret Drive | K3: Novi | L3: MI | M3: US | N3: 48377 | O3: 248-412-9100 | P3: 42.490552 | Q3: -83.48706 | R3: 493 | S3: 0.969 | T3: GWh/yr | U3: Wanxiang A123 | V3: http://www.a123systems.com/ | W3: Hangzhou | X3: Zheijiang | Y3: China | Z3: VP | AA3: 44781 | AB3: Questionnaire; A123systems.com; BNEF Interactive Dataset; Cell manufacturing; https://www.buzzfile.com/business/A123-Systems-LLC-248-412-9249 | AD3: A123 Systems aims to make the air fresher. It leads in batteries and control systems, boasting global patents and a renowned customer base after 20 years of innovation. | AE3: http://www.a123systems.com/ | AF3: =IF(LEN(TRIM(AD3))=0,0,LEN(TRIM(AD3))-LEN(SUBSTITUTE(AD3," ",""))+1) -> 27
A4: 4002 | B4: Commercial | C4: Midstream | D4: ABSL Power Solutions, Inc. | E4: Yes | F4: ABSL Power Solutions, Inc. | G4: Other/ Unknown cells | H4: Other/ Unknown | I4: https://www.enersys.com/en/products/batteries/absl/absl-space/ | J4: 1751 S. Fordham St., Suite 100 | K4: Longmont | L4: CO | M4: US | N4: 80503 | P4: 40.138802 | Q4: -105.14105 | R4: 100 | U4: Enersys | V4: https://www.enersys.com/en/ | W4: Reading | X4: PA | Y4: US | Z4: VP | AA4: 45339 | AB4: Questionnaire | AD4: ABSL manufactures lithium-ion batteries for space applications. It conducts design, structural and thermal analysis to ensure their performance exceeds the most demanding requirements. | AF4: =IF(LEN(TRIM(AD4))=0,0,LEN(TRIM(AD4))-LEN(SUBSTITUTE(AD4," ",""))+1) -> 23 | AG4: Roger Carlone | AH4: roger.carlone@eas.enersys.com
A5: 4003 | B5: Commercial | C5: Midstream | D5: Advanced Battery Concepts | E5: Yes | F5: Advanced Battery Concepts | G5: Cell Manufacturing and Assembly | H5: Sealed Bipolar Lead Acid | I5: https://advancedbatteryconcepts.com/ | J5: 8 Consumers Energy Parkway | K5: Clare | L5: MI | M5: US | N5: 48617 | O5: 989-424-6645 | P5: 43.845834 | Q5: -84.758957 | R5: 50 | U5: Advanced Battery Concepts | V5: https://advancedbatteryconcepts.com/ | W5: Clare | X5: MI | Y5: US | Z5: SD | AA5: 45475 | AB5: https://advancedbatteryconcepts.com/ | AD5: Advanced Battery Concepts delivers economical, socially, and environmentally responsible energy storage solutions with its advanced bipolar battery technology, driving a cleaner, more sustainable future. | AE5: https://advancedbatteryconcepts.com/ | AF5: =IF(LEN(TRIM(AD5))=0,0,LEN(TRIM(AD5))-LEN(SUBSTITUTE(AD5," ",""))+1) -> 24
A6: 4101 | B6: Cancelled | C6: Downstream | D6: Advanced Cell Engineering | F6: Advanced Cell Engineering Inc. | G6: Cell Assemblies/ Groupings | H6: Packs | I6: https://www.advancedcellengineering.com/ | J6: 2634 SE Market Pl | K6: Stuart | L6: FL | M6: US | N6: 34997 | O6: 772-382-9019 | P6: 27.155753 | Q6: -80.217023 | R6: 50 | U6: Advanced Cell Engineering Inc. | V6: https://www.advancedcellengineering.com/ | W6: Stuart | X6: FL | Y6: US | Z6: SD MK | AA6: 2/14/2025 8/27/2025 | AB6: Ahmad's email on 2.13.25; https://www.inforuptcy.com/browse-filings/florida-southern-bankruptcy-court/9:25-bk-16317/bankruptcy-case-advanced-cell-engineering-inc | AC6: The company filed for chapter 7 bankruptcy on June 3, 2025, in the Southern District of Florida | AD6: Advanced Cell Engineering discovers advanced lithium-ion technologies and create better energy storage solutions. Their mission is to accelerate the pace of battery innovation and empower customers. | AF6: =IF(LEN(TRIM(AD6))=0,0,LEN(TRIM(AD6))-LEN(SUBSTITUTE(AD6," ",""))+1) -> 26
A7: 4004 | B7: Commercial | C7: Midstream | D7: AESC | E7: No | F7: US Plant | G7: Prismatic pouch cells | H7: Nickel manganese cobalt | I7: https://www.aesc-group.com/en/ | J7: 500 Battery Plant Road | K7: Smyrna | L7: TN | M7: US | N7: 37167 | O7: 615-768-3505 | P7: 35.960162 | Q7: -86.483048 | R7: 350 | S7: 3 | T7: GWh/yr | U7: AESC | V7: https://www.aesc-group.com/en/ | W7: Zama | X7: Kanagawa | Y7: Japan | Z7: VP MK | AA7: 11/25/2022 8/14/2025 | AB7: BNEF: Interactive Datasets/Storage/Cell manufacturers; envision-aesc.com; https://www.manta.com/c/mkxnxqy/envision-aesc-us-llc#:~:text=Envision%20Aesc%20Us%20Smyrna%20TN%2C%2037167%20%E2%80%93%20Manta.com&text=Categorized%20under%20Computers%20Manufacturers.,a%20staff%20of%20approximately%20350; https://www.automotivemanufacturingsolutions.com/emobility/lithium-ion-battery-gigafactory-database/41937.article;https://www.envision-aesc.com/en/network.html;https://www.apollo.io/companies/Envision-AESC/5e57c2c4f6d38f0001777aae?chart=count; https://source.benchmarkminerals.com/article/lg-chem-tennessee-cathode-plant-could-double-north-american-production?mc_cid=c72c66f531&mc_eid=6a6017029d; https://source.benchmarkminerals.com/article/lg-chem-tennessee-cathode-plant-could-double-north-american-production?mc_cid=c72c66f531&mc_eid=6a6017029d, https://www.bizjournals.com/nashville/news/2025/06/25/aesc-envision-smyrna-battery-factory.html | AC7: Graphite anodes; Facility used to be Nissan factory and was acquired in 2012; Shifting focus from EV to ESS. TBD if this changes chemistry and format. | AD7: AESC Group leads the decarbonization revolution with artificial intelligence converging with the internet of things -driven battery solutions, globally pioneering high-performance EV and energy storage, accelerating the shift to a sustainable future. | AE7: https://www.aesc-group.com/en/, https://www.aesc-group.com/en/aboutus.html | AF7: =IF(LEN(TRIM(AD7))=0,0,LEN(TRIM(AD7))-LEN(SUBSTITUTE(AD7," ",""))+1) -> 31
A8: 4005 | B8: Paused construction | C8: Midstream | D8: AESC | E8: No | F8: Florence County Electric Battery Gigafactory | G8: Other/ Unknown cells | H8: Other/ Unknown | I8: https://www.aesc-group.com/en/ | J8: Technology and Business Park | K8: Florence | L8: SC | M8: US | P8: 34.19519 | Q8: -79.762675 | R8: 1170 (Planned) | S8: 30 | T8: GWh/yr | U8: AESC | V8: https://www.aesc-group.com/en/ | W8: Zama | X8: Kanagawa | Y8: Japan | Z8: VP MK | AA8: 6/11/2023 8/14/2025 | AB8: BNEF Cell database; https://governor.sc.gov/news/2022-12/envision-aesc-establish-florence-county-electric-vehicle-battery-gigafactory; https://www.electrive.com/2023/06/08/aesc-kicks-off-construction-of-battery-plant-in-south-carolina/#:~:text=Battery%20cell%20manufacturer%20AESC%20(formerly,come%20on%20stream%20in%202026, https://scdailygazette.com/2025/06/05/electric-vehicle-battery-company-halts-construction-of-sc-manufacturing-plant/ | AC8: $810M investment to support BMW; Construction started in June 2023; Resume SOP 202x | AD8: AESC Group leads the decarbonization revolution with artificial intelligence converging with the internet of things -driven battery solutions, globally pioneering high-performance EV and energy storage, accelerating the shift to a sustainable future. | AE8: https://www.aesc-group.com/en/, https://www.aesc-group.com/en/aboutus.html | AF8: =IF(LEN(TRIM(AD8))=0,0,LEN(TRIM(AD8))-LEN(SUBSTITUTE(AD8," ",""))+1) -> 31
A9: 4006 | B9: Paused construction | C9: Midstream | D9: AESC | E9: No | F9: Bowling Green Plant | G9: Other/ Unknown cells | H9: Nickel manganese cobalt | I9: https://www.aesc-group.com/en/ | J9: Kentucky Transpark | K9: Bowling Green | L9: KY | M9: US | N9: 42101 | O9: 502-377-5675 | P9: 37.04 | Q9: -86.3 | R9: 2000 (Planned) | S9: 30 | T9: GWh/yr | U9: Envision | V9: https://spectrumnews1.com/ky/bowling-green/news/2022/04/26/envision-aesc-plans-to-establish--2-billion-gigafactory-in-kentucky, https://ced.ky.gov/Newsroom/NewsPage/20220830_EnvisionAESCGroundbreaking | W9: Zama | X9: Kanagawa | Y9: Japan | Z9: VP MK | AA9: 6/19/2023 8/14/2025 | AB9: https://spectrumnews1.com/ky/bowling-green/news/2022/04/26/envision-aesc-plans-to-establish--2-billion-gigafactory-in-kentucky; BNEF Interactive Dataset Cell Manufacturing; https://ced.ky.gov/Newsroom/NewsPage/20220830_EnvisionAESCGroundbreaking, https://www.wsj.com/business/autos/china-aesc-battery-2d61cc41 | AC9: Commissioning expected by EOY 2027; $2B investment; SOP 202x | AD9: AESC Group leads the decarbonization revolution with artificial intelligence converging with the internet of things -driven battery solutions, globally pioneering high-performance EV and energy storage, accelerating the shift to a sustainable future. | AE9: https://www.aesc-group.com/en/, https://www.aesc-group.com/en/aboutus.html | AF9: =IF(LEN(TRIM(AD9))=0,0,LEN(TRIM(AD9))-LEN(SUBSTITUTE(AD9," ",""))+1) -> 31
A10: 4007 | B10: Pre-commercial/ startup | C10: Midstream | D10: Æsir Technologies, Inc. | E10: No | F10: R&D Facility | G10: Battery Development | H10: Rechargeable aqueous hybrid battery | I10: https://www.aesirtec.com | J10: 960 Technology Blvd. Suite 1 | K10: Bozeman | L10: MT | M10: US | N10: 59718 | O10: 417-553-0237 | P10: 45.669674 | Q10: -111.06596 | R10: 50 | U10: Æsir Technologies, Inc. | V10: https://www.aesirtec.com | W10: Joplin | X10: MO | Y10: US | Z10: MK | AA10: 45584 | AB10: https://www.aesirtec.com/LithiumZinc | AC10: Plans to offer nano material additives to Li-ion market this year (6 tpy), alkaline market in 2023 (350 tpy), and rechargeable markets in 2025 (5000 tpy) | AD10: Æsir Technologies develops lithium-zinc batteries offering enhanced cycle life, energy density, and safety. Its rechargeable aqueous hybrid battery technology provides sustainable, recyclable, and non-toxic energy storage solutions. | AF10: =IF(LEN(TRIM(AD10))=0,0,LEN(TRIM(AD10))-LEN(SUBSTITUTE(AD10," ",""))+1) -> 27 | AH10: info@aesirtec.com | AI10: 417-553-0237
A11: 4009 | B11: Under construction | C11: Midstream | D11: American Battery Factory | E11: Yes | F11: American Battery Factory | G11: Prismatic metal can cells | H11: Lithium iron phosphate | I11: https://americanbatteryfactory.com/ | J11: Aerospace Research Campus - I10 and South Rita Road | K11: Tucson | L11: AZ | M11: US | N11: 84003 | O11: 385-269-2061 | P11: 32.089065 | Q11: -110.80434 | R11: 1000 (Planned) | S11: 4 | T11: GWh/yr | U11: American Battery Factory | V11: https://americanbatteryfactory.com/ | W11: American Fork | X11: UT | Y11: US | Z11: VP MK | AA11: 1/13/2024 8/14/2025 | AB11: Questionnaire; telecon 8/20/21; BNEF Interactive Dataset Cell Manufacturing; https://pv-magazine-usa.com/2022/03/08/plans-announced-for-a-us-lithium-ferro-phosphate-battery-gigafactory-network/; https://americanbatteryfactory.com/press/2023-10-26-american-battery-factory-breaks-ground; https://content.civicplus.com/api/assets/ae999a10-d4d7-473b-8b3b-772516ff2b30 | AC11: $1.2B capital investment; SOP 2027; Targeting 20 GWh eventually | AD11: American Battery Factory revolutionizes energy with U.S.-owned vertical manufacturing for LFP battery cells, integrating software, hardware, and technology to ensure renewable, independent, and affordable energy. | AE11: https://americanbatteryfactory.com/ | AF11: =IF(LEN(TRIM(AD11))=0,0,LEN(TRIM(AD11))-LEN(SUBSTITUTE(AD11," ",""))+1) -> 24
A12: 4010 | B12: Commercial | C12: Midstream | D12: American Lithium Energy | E12: No | F12: ALEC | G12: Other/ Unknown cells | H12: Other/ Unknown | I12: https://www.americanlithiumenergy.com/ | J12: 1395 Aspen Way | K12: Vista | L12: CA | M12: US | N12: 92008 | O12: 760-444-5244 | P12: 33.136255 | Q12: -117.24337 | R12: 30 | U12: American Lithium Energy | V12: https://www.americanlithiumenergy.com/ | W12: Carlsbad | X12: CA | Y12: US | Z12: VP MK | AA12: 45896 | AB12: americanlithiumenergy.com; Questionnaire; https://www.dnb.com/business-directory/company-profiles.american_lithium_energy_corp.eb6cbeb7e4a7cbf5bd0c71ced5c81852.html;https://lithiumamericas.com/usa/thacker-pass/; https://www.connectcre.com/stories/lithium-ion-battery-maker-nearly-quadruples-space-in-move-to-vista/ | AC12: Focuses on batteries and packs for military applications | AD12: American Lithium Energy leads with the world's highest energy density silicon-based lithium-ion batteries, setting industry safety benchmarks. Its patented technologies ensure powerful, long-lasting, and safe cells, eliminating trade-offs in energy density, life cycle, and safety. | AE12: https://www.americanlithiumenergy.com/, https://www.americanlithiumenergy.com/about | AF12: =IF(LEN(TRIM(AD12))=0,0,LEN(TRIM(AD12))-LEN(SUBSTITUTE(AD12," ",""))+1) -> 34
A13: 4099 | B13: Under construction | C13: Midstream | D13: Amplify Cell Technologies | E13: No | F13: Marshall County Battery Cell Manufacturing Plant | G13: Cell | H13: Lithium-iron-phosphate battery cells | I13: https://amplifycelltech.com/ | J13: Chickasaw Trail Industrial Park | K13: Byhalia | L13: MS | M13: US | P13: 34.870605 | Q13: -89.69072 | R13: 2000 | S13: 21 | T13: Gwh/yr | U13: Amplify Cell Technologies | V13: https://amplifycelltech.com/ | W13: Byhalia | X13: MS | Y13: US | Z13: MK | AA13: 2/5/2025 8/14/2025 | AB13: https://www.paccar.com/news/current-news/2024/amplify-cell-technologies-begins-construction-of-mississippi-battery-cell-factory/, https://www.daimlertruck.com/en/newsroom/pressrelease/amplify-cell-technologies-a-joint-venture-between-accelera-by-cummins-daimler-truck-and-paccar-begins-construction-of-mississippi-battery-cell-factory-52757135; https://www.linkedin.com/posts/jack-baldwin-1052b1188_aviation-construction-constructionjobs-activity-7343246539114332160-qCgy/ | AC13: 2027 SOP | AD13: Amplify Cell Technologies produces lithium-iron-phosphate battery cells for electric commercial vehicles. | AF13: =IF(LEN(TRIM(AD13))=0,0,LEN(TRIM(AD13))-LEN(SUBSTITUTE(AD13," ",""))+1) -> 11
